Workbook

Sheet NQ_Trades
A1: NQ Bull Call Spread — Paper Trading Journal
A2: Date | B2: Instrument | C2: Strategy | D2: Expiry Date | E2: DTE | F2: Entry Time | G2: Exit Time | H2: Spot at Entry | I2: Buy Strike | J2: Sell Strike | K2: Contracts | L2: Entry Premium | M2: Exit Premium | N2: Total Cost ($) | O2: Max Profit ($) | P2: Target ($) | Q2: Stop Loss ($) | R2: Gross P&L ($) | S2: Return % | T2: CME Fee ($) | U2: Broker Fee ($) | V2: NFA Fee ($) | W2: Total Fees ($) | X2: Net P&L ($) | Y2: Outcome | Z2: Budget ($) | AA2: Mode
A3: 2026-06-15 | B3: NQ | C3: Bull Call Spread | D3: 2026-06-19 | E3: 4 | F3: 10:00 ET | G3: 15:28 ET | H3: 30863 | I3: 30850 | J3: 30875 | K3: 7 | L3: 121.65 | M3: 125.64 | N3: 903.35 | O3: 2648.45 | P3: 255.46 | Q3: 255.46 | R3: 27.93 | S3: 3.3 | T3: 16.52 | U3: 35 | V3: 0.28 | W3: 51.8 | X3: -23.87 | Y3: FLAT | Z3: 1000 | AA3: PAPER TRADING
A4: 2026-06-17 | B4: NQ | C4: Bull Call Spread | D4: 2026-06-19 | E4: 2 | F4: 10:00 ET | G4: 15:00 ET | H4: 30463.75 | I4: 30450 | J4: 30475 | K4: 6 | L4: 139.72 | M4: 144.35 | N4: 882.72 | O4: 2161.68 | P4: 251.5 | Q4: 251.5 | R4: 27.78 | S4: 3.3 | T4: 14.16 | U4: 30 | V4: 0.24 | W4: 44.4 | X4: -16.62 | Y4: FLAT | Z4: 1000 | AA4: PAPER TRADING
A5: 2026-06-18 | B5: NQ | C5: Bull Call Spread | D5: 2026-06-19 | E5: 1 | F5: 10:00 ET | G5: 12:26 ET | H5: 30623.75 | I5: 30600 | J5: 30625 | K5: 6 | L5: 148 | M5: 103.6 | N5: 932.4 | O5: 2112 | P5: 266.4 | Q5: 266.4 | R5: -266.4 | S5: -30 | T5: 14.16 | U5: 30 | V5: 0.24 | W5: 44.4 | X5: -310.8 | Y5: STOP LOSS | Z5: 1000 | AA5: PAPER TRADING
A6: 2026-06-18 | B6: NQ | C6: Bull Call Spread | D6: 2026-06-19 | E6: 1 | F6: 10:00 ET | G6: 11:07 ET | H6: 30542.25 | I6: 30525 | J6: 30550 | K6: 7 | L6: 117.73 | M6: 153.05 | N6: 875.91 | O6: 2675.89 | P6: 247.23 | Q6: 247.23 | R6: 247.24 | S6: 30 | T6: 16.52 | U6: 35 | V6: 0.28 | W6: 51.8 | X6: 195.44 | Y6: PROFIT | Z6: 1000 | AA6: PAPER TRADING
A7: 2026-06-19 | B7: NQ | C7: Bull Call Spread | D7: 2026-07-17 | E7: 28 | F7: 10:00 ET | G7: 15:16 ET | H7: 30506.5 | I7: 30500 | J7: 30525 | K7: 4 | L7: 226.7 | M7: 221.29 | N7: 936.4 | O7: 1093.2 | P7: 272.04 | Q7: 272.04 | R7: -21.64 | S7: -2.4 | T7: 9.44 | U7: 20 | V7: 0.16 | W7: 29.6 | X7: -51.24 | Y7: FLAT | Z7: 1000 | AA7: PAPER TRADING
A8: 2026-06-19 | B8: NQ | C8: Bull Call Spread | D8: 2026-07-17 | E8: 28 | F8: 10:00 ET | G8: 11:01 ET | H8: 30506.5 | I8: 30500 | J8: 30525 | K8: 4 | L8: 238.22 | M8: 166.75 | N8: 982.48 | O8: 1047.12 | P8: 285.86 | Q8: 285.86 | R8: -285.88 | S8: -30 | T8: 9.44 | U8: 20 | V8: 0.16 | W8: 29.6 | X8: -315.48 | Y8: STOP LOSS | Z8: 1000 | AA8: PAPER TRADING
A9: 2026-06-22 | B9: NQ | C9: Bull Call Spread | D9: 2026-07-17 | E9: 25 | F9: 10:00 ET | G9: 12:16 ET | H9: 30627.75 | I9: 30625 | J9: 30650 | K9: 3 | L9: 267.2 | M9: 347.36 | N9: 823.8 | O9: 698.4 | P9: 240.48 | Q9: 240.48 | R9: 240.48 | S9: 30 | T9: 7.08 | U9: 15 | V9: 0.12 | W9: 22.2 | X9: 218.28 | Y9: PROFIT | Z9: 1000 | AA9: PAPER TRADING
A10: 2026-06-22 | B10: NQ | C10: Bull Call Spread | D10: 2026-07-17 | E10: 25 | F10: 10:00 ET | G10: 11:12 ET | H10: 30662.5 | I10: 30650 | J10: 30675 | K10: 4 | L10: 237.6 | M10: 308.88 | N10: 980 | O10: 1049.6 | P10: 285.12 | Q10: 285.12 | R10: 285.12 | S10: 30 | T10: 9.44 | U10: 20 | V10: 0.16 | W10: 29.6 | X10: 255.52 | Y10: PROFIT | Z10: 1000 | AA10: PAPER TRADING
A11: 2026-06-23 | B11: NQ | C11: Bull Call Spread | D11: 2026-07-17 | E11: 24 | F11: 10:00 ET | G11: 13:39 ET | H11: 29686 | I11: 29675 | J11: 29700 | K11: 3 | L11: 249.78 | M11: 324.71 | N11: 771.54 | O11: 750.66 | P11: 224.8 | Q11: 224.8 | R11: 224.79 | S11: 30 | T11: 7.08 | U11: 15 | V11: 0.12 | W11: 22.2 | X11: 202.59 | Y11: PROFIT | Z11: 1000 | AA11: PAPER TRADING
A12: 2026-06-23 | B12: NQ | C12: Bull Call Spread | D12: 2026-07-17 | E12: 24 | F12: 10:00 ET | G12: 11:47 ET | H12: 29732.5 | I12: 29725 | J12: 29750 | K12: 3 | L12: 254.03 | M12: 330.24 | N12: 784.29 | O12: 737.91 | P12: 228.63 | Q12: 228.63 | R12: 228.63 | S12: 30 | T12: 7.08 | U12: 15 | V12: 0.12 | W12: 22.2 | X12: 206.43 | Y12: PROFIT | Z12: 1000 | AA12: PAPER TRADING
A13: 2026-06-24 | B13: NQ | C13: Bull Call Spread | D13: 2026-07-17 | E13: 23 | F13: 10:00 ET | G13: 12:03 ET | H13: 29866.25 | I13: 29850 | J13: 29875 | K13: 3 | L13: 246.52 | M13: 320.48 | N13: 761.76 | O13: 760.44 | P13: 221.87 | Q13: 221.87 | R13: 221.88 | S13: 30 | T13: 7.08 | U13: 15 | V13: 0.12 | W13: 22.2 | X13: 199.68 | Y13: PROFIT | Z13: 1000 | AA13: PAPER TRADING
A14: 2026-06-24 | B14: NQ | C14: Bull Call Spread | D14: 2026-07-17 | E14: 23 | F14: 10:00 ET | G14: 13:10 ET | H14: 29838 | I14: 29825 | J14: 29850 | K14: 3 | L14: 268.69 | M14: 349.3 | N14: 828.27 | O14: 693.93 | P14: 241.82 | Q14: 241.82 | R14: 241.83 | S14: 30 | T14: 7.08 | U14: 15 | V14: 0.12 | W14: 22.2 | X14: 219.63 | Y14: PROFIT | Z14: 1000 | AA14: PAPER TRADING
... A190: 2026-10-29 | B190: NQ | C190: Bull Call Spread | D190: 2026-11-20 | E190: 22 | F190: 10:00 ET | G190: 12:14 ET | H190: 29688.25 | I190: 29675 | J190: 29700 | K190: 3 | L190: 258.48 | M190: 336.02 | N190: 797.64 | O190: 724.56 | P190: 232.63 | Q190: 232.63 | R190: 232.62 | S190: 30 | T190: 7.08 | U190: 15 | V190: 0.12 | W190: 22.2 | X190: 210.42 | Y190: PROFIT | Z190: 1000 | AA190: PAPER TRADING

Sheet MNQ_Trades
A1: MNQ Bull Call Spread — Paper Trading Journal
A2: Date | B2: Instrument | C2: Strategy | D2: Expiry Date | E2: DTE | F2: Entry Time | G2: Exit Time | H2: Spot at Entry | I2: Buy Strike | J2: Sell Strike | K2: Contracts | L2: Entry Premium | M2: Exit Premium | N2: Total Cost ($) | O2: Max Profit ($) | P2: Target ($) | Q2: Stop Loss ($) | R2: Gross P&L ($) | S2: Return % | T2: CME Fee ($) | U2: Broker Fee ($) | V2: NFA Fee ($) | W2: Total Fees ($) | X2: Net P&L ($) | Y2: Outcome | Z2: Budget ($) | AA2: Mode
A3: 2026-06-15 | B3: MNQ | C3: Bull Call Spread | D3: 2026-06-19 | E3: 4 | F3: 10:00 ET | G3: 16:20 ET | H3: 30863.75 | I3: 30850 | J3: 30875 | K3: 78 | L3: 11.14 | M3: 11.18 | N3: 996.84 | O3: 3031.08 | P3: 260.68 | Q3: 260.68 | R3: 3.12 | S3: 0.4 | T3: 46.8 | U3: 78 | V3: 3.12 | W3: 127.92 | X3: -124.8 | Y3: FLAT | Z3: 1000 | AA3: PAPER TRADING
A4: 2026-06-17 | B4: MNQ | C4: Bull Call Spread | D4: 2026-06-19 | E4: 2 | F4: 10:00 ET | G4: 11:01 ET | H4: 30463.75 | I4: 30450 | J4: 30475 | K4: 60 | L4: 14.8 | M4: 10.36 | N4: 986.4 | O4: 2112 | P4: 266.4 | Q4: 266.4 | R4: -266.4 | S4: -30 | T4: 36 | U4: 60 | V4: 2.4 | W4: 98.4 | X4: -364.8 | Y4: STOP LOSS | Z4: 1000 | AA4: PAPER TRADING
A5: 2026-06-18 | B5: MNQ | C5: Bull Call Spread | D5: 2026-06-19 | E5: 1 | F5: 10:00 ET | G5: 10:58 ET | H5: 30623.5 | I5: 30600 | J5: 30625 | K5: 63 | L5: 14.18 | M5: 9.93 | N5: 996.66 | O5: 2256.66 | P5: 268 | Q5: 268 | R5: -267.75 | S5: -30 | T5: 37.8 | U5: 63 | V5: 2.52 | W5: 103.32 | X5: -371.07 | Y5: STOP LOSS | Z5: 1000 | AA5: PAPER TRADING
A6: 2026-06-18 | B6: MNQ | C6: Bull Call Spread | D6: 2026-06-19 | E6: 1 | F6: 10:00 ET | G6: 12:56 ET | H6: 30546.5 | I6: 30525 | J6: 30550 | K6: 77 | L6: 11.2 | M6: 7.84 | N6: 988.68 | O6: 2987.6 | P6: 258.72 | Q6: 258.72 | R6: -258.72 | S6: -30 | T6: 46.2 | U6: 77 | V6: 3.08 | W6: 126.28 | X6: -385 | Y6: STOP LOSS | Z6: 1000 | AA6: PAPER TRADING
A7: 2026-06-19 | B7: MNQ | C7: Bull Call Spread | D7: 2026-07-17 | E7: 28 | F7: 10:00 ET | G7: 15:28 ET | H7: 30508 | I7: 30500 | J7: 30525 | K7: 40 | L7: 23.2 | M7: 22.86 | N7: 993.6 | O7: 1072 | P7: 278.4 | Q7: 278.4 | R7: -13.6 | S7: -1.5 | T7: 24 | U7: 40 | V7: 1.6 | W7: 65.6 | X7: -79.2 | Y7: FLAT | Z7: 1000 | AA7: PAPER TRADING
A8: 2026-06-19 | B8: MNQ | C8: Bull Call Spread | D8: 2026-07-17 | E8: 28 | F8: 10:00 ET | G8: 11:06 ET | H8: 30508 | I8: 30500 | J8: 30525 | K8: 45 | L8: 20.1 | M8: 14.07 | N8: 978.3 | O8: 1345.5 | P8: 271.35 | Q8: 271.35 | R8: -271.35 | S8: -30 | T8: 27 | U8: 45 | V8: 1.8 | W8: 73.8 | X8: -345.15 | Y8: STOP LOSS | Z8: 1000 | AA8: PAPER TRADING
A9: 2026-06-22 | B9: MNQ | C9: Bull Call Spread | D9: 2026-07-17 | E9: 25 | F9: 10:00 ET | G9: 15:44 ET | H9: 30629 | I9: 30625 | J9: 30650 | K9: 40 | L9: 22.98 | M9: 23.14 | N9: 984.8 | O9: 1080.8 | P9: 275.76 | Q9: 275.76 | R9: 6.4 | S9: 0.7 | T9: 24 | U9: 40 | V9: 1.6 | W9: 65.6 | X9: -59.2 | Y9: FLAT | Z9: 1000 | AA9: PAPER TRADING
A10: 2026-06-22 | B10: MNQ | C10: Bull Call Spread | D10: 2026-07-17 | E10: 25 | F10: 10:00 ET | G10: 11:26 ET | H10: 30662 | I10: 30650 | J10: 30675 | K10: 38 | L10: 24.02 | M10: 31.23 | N10: 975.08 | O10: 987.24 | P10: 273.83 | Q10: 273.83 | R10: 273.98 | S10: 30 | T10: 22.8 | U10: 38 | V10: 1.52 | W10: 62.32 | X10: 211.66 | Y10: PROFIT | Z10: 1000 | AA10: PAPER TRADING
A11: 2026-06-23 | B11: MNQ | C11: Bull Call Spread | D11: 2026-07-17 | E11: 24 | F11: 10:00 ET | G11: 12:28 ET | H11: 29673.25 | I11: 29650 | J11: 29675 | K11: 44 | L11: 20.9 | M11: 14.63 | N11: 991.76 | O11: 1280.4 | P11: 275.88 | Q11: 275.88 | R11: -275.88 | S11: -30 | T11: 26.4 | U11: 44 | V11: 1.76 | W11: 72.16 | X11: -348.04 | Y11: STOP LOSS | Z11: 1000 | AA11: PAPER TRADING
A12: 2026-06-23 | B12: MNQ | C12: Bull Call Spread | D12: 2026-07-17 | E12: 24 | F12: 10:00 ET | G12: 15:52 ET | H12: 29731.75 | I12: 29725 | J12: 29750 | K12: 35 | L12: 26.55 | M12: 25.24 | N12: 986.65 | O12: 820.75 | P12: 278.77 | Q12: 278.77 | R12: -45.85 | S12: -4.9 | T12: 21 | U12: 35 | V12: 1.4 | W12: 57.4 | X12: -103.25 | Y12: FLAT | Z12: 1000 | AA12: PAPER TRADING
A13: 2026-06-24 | B13: MNQ | C13: Bull Call Spread | D13: 2026-07-17 | E13: 23 | F13: 10:00 ET | G13: 12:54 ET | H13: 29867.5 | I13: 29850 | J13: 29875 | K13: 37 | L13: 24.81 | M13: 32.25 | N13: 978.65 | O13: 932.03 | P13: 275.39 | Q13: 275.39 | R13: 275.28 | S13: 30 | T13: 22.2 | U13: 37 | V13: 1.48 | W13: 60.68 | X13: 214.6 | Y13: PROFIT | Z13: 1000 | AA13: PAPER TRADING
A14: 2026-06-24 | B14: MNQ | C14: Bull Call Spread | D14: 2026-07-17 | E14: 23 | F14: 10:00 ET | G14: 10:29 ET | H14: 29836.5 | I14: 29825 | J14: 29850 | K14: 39 | L14: 23.64 | M14: 16.55 | N14: 985.92 | O14: 1028.04 | P14: 276.59 | Q14: 276.59 | R14: -276.51 | S14: -30 | T14: 23.4 | U14: 39 | V14: 1.56 | W14: 63.96 | X14: -340.47 | Y14: STOP LOSS | Z14: 1000 | AA14: PAPER TRADING
... A190: 2026-10-29 | B190: MNQ | C190: Bull Call Spread | D190: 2026-11-20 | E190: 22 | F190: 10:00 ET | G190: 11:53 ET | H190: 29687.5 | I190: 29675 | J190: 29700 | K190: 43 | L190: 21.52 | M190: 27.98 | N190: 995.88 | O190: 1224.64 | P190: 277.61 | Q190: 277.61 | R190: 277.78 | S190: 30 | T190: 25.8 | U190: 43 | V190: 1.72 | W190: 70.52 | X190: 207.26 | Y190: PROFIT | Z190: 1000 | AA190: PAPER TRADING

Sheet US_Stocks
A1: US Stocks — Paper Trading Journal
A2: Date | B2: Ticker | C2: Company | D2: Action | E2: Qty | F2: Entry Price | G2: Exit Price | H2: Gross P&L ($) | I2: Broker Fee ($) | J2: Net P&L ($) | K2: Outcome | L2: Notes

Sheet Fee_Breakdown
A1: Fee Breakdown — All Instruments
A2: Date | B2: Instrument | C2: Contracts | D2: CME Fee/Leg ($) | E2: Broker Fee/Leg ($) | F2: NFA Fee/Leg ($) | G2: Total/Leg ($) | H2: Round-Trip Total ($) | I2: Notes
A3: 2026-06-15 | B3: NQ | C3: 7 | D3: 8.26 | E3: 17.5 | F3: 0.14 | G3: 25.9 | H3: 51.8 | I3: NQ Bull Call Spread — FLAT
A4: 2026-06-15 | B4: MNQ | C4: 78 | D4: 23.4 | E4: 39 | F4: 1.56 | G4: 63.96 | H4: 127.92 | I4: MNQ Bull Call Spread — FLAT
A5: 2026-06-17 | B5: NQ | C5: 6 | D5: 7.08 | E5: 15 | F5: 0.12 | G5: 22.2 | H5: 44.4 | I5: NQ Bull Call Spread — FLAT
A6: 2026-06-17 | B6: MNQ | C6: 60 | D6: 18 | E6: 30 | F6: 1.2 | G6: 49.2 | H6: 98.4 | I6: MNQ Bull Call Spread — STOP LOSS
A7: 2026-06-18 | B7: NQ | C7: 6 | D7: 7.08 | E7: 15 | F7: 0.12 | G7: 22.2 | H7: 44.4 | I7: NQ Bull Call Spread — STOP LOSS
A8: 2026-06-18 | B8: MNQ | C8: 63 | D8: 18.9 | E8: 31.5 | F8: 1.26 | G8: 51.66 | H8: 103.32 | I8: MNQ Bull Call Spread — STOP LOSS
A9: 2026-06-18 | B9: NQ | C9: 7 | D9: 8.26 | E9: 17.5 | F9: 0.14 | G9: 25.9 | H9: 51.8 | I9: NQ Bull Call Spread — PROFIT
A10: 2026-06-18 | B10: MNQ | C10: 77 | D10: 23.1 | E10: 38.5 | F10: 1.54 | G10: 63.14 | H10: 126.28 | I10: MNQ Bull Call Spread — STOP LOSS
A11: 2026-06-19 | B11: NQ | C11: 4 | D11: 4.72 | E11: 10 | F11: 0.08 | G11: 14.8 | H11: 29.6 | I11: NQ Bull Call Spread — FLAT
A12: 2026-06-19 | B12: MNQ | C12: 40 | D12: 12 | E12: 20 | F12: 0.8 | G12: 32.8 | H12: 65.6 | I12: MNQ Bull Call Spread — FLAT
A13: 2026-06-19 | B13: NQ | C13: 4 | D13: 4.72 | E13: 10 | F13: 0.08 | G13: 14.8 | H13: 29.6 | I13: NQ Bull Call Spread — STOP LOSS
A14: 2026-06-19 | B14: MNQ | C14: 45 | D14: 13.5 | E14: 22.5 | F14: 0.9 | G14: 36.9 | H14: 73.8 | I14: MNQ Bull Call Spread — STOP LOSS
... A378: 2026-10-29 | B378: MNQ | C378: 43 | D378: 12.9 | E378: 21.5 | F378: 0.86 | G378: 35.26 | H378: 70.52 | I378: MNQ Bull Call Spread — PROFIT

Sheet Summary
A1: PAPER TRADING — PERFORMANCE SUMMARY
A2: NQ — Bull Call Spread
A3: Total Trades | B3: =COUNTA(NQ_Trades!A3:A1000) | C3: NQ
A4: Wins | B4: =COUNTIF(NQ_Trades!Y3:Y1000,"PROFIT") | C4: NQ
A5: Losses | B5: =COUNTIF(NQ_Trades!Y3:Y1000,"STOP LOSS") | C5: NQ
A6: Flat | B6: =COUNTIF(NQ_Trades!Y3:Y1000,"FLAT") | C6: NQ
A7: Win Rate (%) | B7: =IFERROR(B4/B3*100,0) | C7: NQ
A8: Gross P&L ($) | B8: =IFERROR(SUM(NQ_Trades!R3:R1000),0) | C8: NQ
A9: Total Fees ($) | B9: =IFERROR(SUM(NQ_Trades!V3:V1000),0) | C9: NQ
A10: Net P&L ($) | B10: =IFERROR(SUM(NQ_Trades!W3:W1000),0) | C10: NQ
A11: Budget ($) | B11: 1000 | C11: NQ
A12: Return on Budget (%) | B12: =IFERROR(B10/B11*100,0) | C12: NQ
A14: MNQ — Bull Call Spread
A15: Total Trades | B15: =COUNTA(MNQ_Trades!A3:A1000) | C15: MNQ
A16: Wins | B16: =COUNTIF(MNQ_Trades!Y3:Y1000,"PROFIT") | C16: MNQ
A17: Losses | B17: =COUNTIF(MNQ_Trades!Y3:Y1000,"STOP LOSS") | C17: MNQ
A18: Flat | B18: =COUNTIF(MNQ_Trades!Y3:Y1000,"FLAT") | C18: MNQ
A19: Win Rate (%) | B19: =IFERROR(B16/B15*100,0) | C19: MNQ
A20: Gross P&L ($) | B20: =IFERROR(SUM(MNQ_Trades!R3:R1000),0) | C20: MNQ
A21: Total Fees ($) | B21: =IFERROR(SUM(MNQ_Trades!V3:V1000),0) | C21: MNQ
A22: Net P&L ($) | B22: =IFERROR(SUM(MNQ_Trades!W3:W1000),0) | C22: MNQ
A23: Budget ($) | B23: 1000 | C23: MNQ
A24: Return on Budget (%) | B24: =IFERROR(B22/B23*100,0) | C24: MNQ
A26: Combined Totals
A27: Total Net P&L ($) | B27: =B10+B22
A28: Total Fees Paid ($) | B28: =B9+B21
A29: Overall Win Rate (%) | B29: =IFERROR((B4+B16)/(B3+B15)*100,0)

Sheet NIFTY_BullCall
A1: NIFTY — Bull Call Spread | Paper Trading
A2: Date | B2: Instrument | C2: Strategy Mode | D2: Spread | E2: Trend | F2: Trend Reason | G2: EMA 9 | H2: EMA 21 | I2: Expiry | J2: Expiry Type | K2: DTE | L2: Entry Time | M2: Exit Time | N2: Spot at Entry | O2: Prev Close | P2: Buy Strike | Q2: Sell Strike | R2: Lots | S2: Lot Size | T2: Units | U2: Entry Premium | V2: Exit Premium | W2: Total Cost (₹) | X2: Capital Used (₹) | Y2: Max Profit (₹) | Z2: Target (₹) | AA2: Stop Loss (₹) | AB2: Gross P&L (₹) | AC2: Return % | AD2: Brokerage (₹) | AE2: STT (₹) | AF2: SEBI Fee (₹) | AG2: Stamp Duty (₹) | AH2: GST (₹) | AI2: Total Fees (₹) | AJ2: Net P&L (₹) | AK2: Outcome | AL2: Budget (₹) | AM2: Mode
A3: 2026-06-16 | B3: NIFTY | C3: Bull Call Spread | D3: Bull Call Spread | E3: SKIP | F3: Conflicting — Price:BULLISH EMA:BEARISH | G3: 23385.72 | H3: 23538 | I3: 2026-06-18 | J3: WEEKLY | K3: 3 | L3: 09:20 IST | M3: 11:02 IST | N3: 23622.9 | O3: 23161.6 | P3: 23600 CE | Q3: 23700 CE | R3: 20 | S3: 75 | T3: 1500 | U3: 31.47 | V3: 22.03 | W3: 47205 | X3: 47259.63 | Y3: 102795 | Z3: 14161.5 | AA3: 14161.5 | AB3: -14160 | AC3: -30 | AD3: 40 | AE3: 5.9 | AF3: 0.09 | AG3: 1.42 | AH3: 7.22 | AI3: 54.63 | AJ3: -14214.63 | AK3: STOP LOSS | AL3: 50000 | AM3: PAPER TRADING
A4: 2026-06-18 | B4: NIFTY | C4: Bull Call Spread | D4: Bull Call Spread | E4: BULLISH | F4: Price↑(24168.0>24085.7) & EMA9↑(23778.35>23687.38) | G4: 23778.35 | H4: 23687.38 | I4: 2026-06-18 | J4: WEEKLY | K4: 0 | L4: 09:20 IST | M4: 10:29 IST | N4: 24168 | O4: 24085.7 | P4: 24100 CE | Q4: 24200 CE | R4: 26 | S4: 75 | T4: 1950 | U4: 24.87 | V4: 32.33 | W4: 48496.5 | X4: 48551.33 | Y4: 146503.5 | Z4: 14548.95 | AA4: 14548.95 | AB4: 14547 | AC4: 30 | AD4: 40 | AE4: 6.06 | AF4: 0.1 | AG4: 1.45 | AH4: 7.22 | AI4: 54.83 | AJ4: 14492.17 | AK4: PROFIT | AL4: 50000 | AM4: PAPER TRADING
A5: 2026-06-19 | B5: NIFTY | C5: Bull Call Spread | D5: Bull Call Spread | E5: SKIP | F5: Conflicting — Price:BEARISH EMA:BULLISH | G5: 23824.67 | H5: 23712.22 | I5: 2026-06-25 | J5: WEEKLY | K5: 6 | L5: 09:20 IST | M5: 10:43 IST | N5: 24013.1 | O5: 24168 | P5: 24000 CE | Q5: 24100 CE | R5: 19 | S5: 75 | T5: 1425 | U5: 33.25 | V5: 23.27 | W5: 47381.25 | X5: 47435.91 | Y5: 95118.75 | Z5: 14214.38 | AA5: 14214.38 | AB5: -14221.5 | AC5: -30 | AD5: 40 | AE5: 5.92 | AF5: 0.09 | AG5: 1.42 | AH5: 7.22 | AI5: 54.66 | AJ5: -14276.16 | AK5: STOP LOSS | AL5: 50000 | AM5: PAPER TRADING
A6: 2026-06-20 | B6: NIFTY | C6: Bull Call Spread | D6: Bull Call Spread | E6: BULLISH | F6: Price↑(24168.0>24085.7) & EMA9↑(23777.57>23682.14) | G6: 23777.57 | H6: 23682.14 | I6: 2026-06-25 | J6: WEEKLY | K6: 6 | L6: 09:20 IST | M6: 10:31 IST | N6: 24168 | O6: 24085.7 | P6: 24100 CE | Q6: 24200 CE | R6: 23 | S6: 75 | T6: 1725 | U6: 27.64 | V6: 19.35 | W6: 47679 | X6: 47733.7 | Y6: 124821 | Z6: 14303.7 | AA6: 14303.7 | AB6: -14300.25 | AC6: -30 | AD6: 40 | AE6: 5.96 | AF6: 0.1 | AG6: 1.43 | AH6: 7.22 | AI6: 54.7 | AJ6: -14354.95 | AK6: STOP LOSS | AL6: 50000 | AM6: PAPER TRADING
A7: 2026-06-23 | B7: NIFTY | C7: Bull Call Spread | D7: Bull Call Spread | E7: SKIP | F7: Conflicting — Price:BEARISH EMA:BULLISH | G7: 23824.22 | H7: 23714.31 | I7: 2026-06-25 | J7: WEEKLY | K7: 3 | L7: 09:20 IST | M7: 14:04 IST | N7: 24013.1 | O7: 24168 | P7: 24000 CE | Q7: 24100 CE | R7: 21 | S7: 75 | T7: 1575 | U7: 30.13 | V7: 29.89 | W7: 47454.75 | X7: 47509.42 | Y7: 110045.25 | Z7: 14236.42 | AA7: 14236.42 | AB7: -378 | AC7: -0.8 | AD7: 40 | AE7: 5.93 | AF7: 0.09 | AG7: 1.42 | AH7: 7.22 | AI7: 54.67 | AJ7: -432.67 | AK7: FLAT | AL7: 50000 | AM7: PAPER TRADING
A8: 2026-06-23 | B8: NIFTY | C8: Bull Call Spread | D8: Bull Call Spread | E8: SKIP | F8: Conflicting — Price:BEARISH EMA:BULLISH | G8: 23824.22 | H8: 23714.31 | I8: 2026-06-25 | J8: WEEKLY | K8: 3 | L8: 09:20 IST | M8: 10:18 IST | N8: 24013.1 | O8: 24168 | P8: 24000 CE | Q8: 24100 CE | R8: 18 | S8: 75 | T8: 1350 | U8: 36.35 | V8: 25.45 | W8: 49072.5 | X8: 49127.42 | Y8: 85927.5 | Z8: 14721.75 | AA8: 14721.75 | AB8: -14715 | AC8: -30 | AD8: 40 | AE8: 6.13 | AF8: 0.1 | AG8: 1.47 | AH8: 7.22 | AI8: 54.92 | AJ8: -14769.92 | AK8: STOP LOSS | AL8: 50000 | AM8: PAPER TRADING
A9: 2026-06-23 | B9: NIFTY | C9: Bull Call Spread | D9: Bull Call Spread | E9: SKIP | F9: Conflicting — Price:BEARISH EMA:BULLISH | G9: 23868.63 | H9: 23767.86 | I9: 2026-06-25 | J9: WEEKLY | K9: 2 | L9: 09:20 IST | M9: 10:03 IST | N9: 23824.1 | O9: 24102.9 | P9: 23800 CE | Q9: 23900 CE | R9: 31 | S9: 75 | T9: 2325 | U9: 20.81 | V9: 27.05 | W9: 48383.25 | X9: 48438.06 | Y9: 184116.75 | Z9: 14514.98 | AA9: 14514.98 | AB9: 14508 | AC9: 30 | AD9: 40 | AE9: 6.05 | AF9: 0.1 | AG9: 1.45 | AH9: 7.22 | AI9: 54.81 | AJ9: 14453.19 | AK9: PROFIT | AL9: 50000 | AM9: PAPER TRADING
A10: 2026-06-24 | B10: NIFTY | C10: Bull Call Spread | D10: Bull Call Spread | E10: BULLISH | F10: Price↑(24102.9>24013.1) & EMA9↑(23879.76>23762.23) | G10: 23879.76 | H10: 23762.23 | I10: 2026-06-25 | J10: WEEKLY | K10: 2 | L10: 09:20 IST | M10: 11:19 IST | N10: 24102.9 | O10: 24013.1 | P10: 24100 CE | Q10: 24200 CE | R10: 27 | S10: 75 | T10: 2025 | U10: 23.46 | V10: 30.5 | W10: 47506.5 | X10: 47561.18 | Y10: 154993.5 | Z10: 14251.95 | AA10: 14251.95 | AB10: 14256 | AC10: 30 | AD10: 40 | AE10: 5.94 | AF10: 0.1 | AG10: 1.43 | AH10: 7.22 | AI10: 54.68 | AJ10: 14201.32 | AK10: PROFIT | AL10: 50000 | AM10: PAPER TRADING
A11: 2026-06-24 | B11: NIFTY | C11: Bull Call Spread | D11: Bull Call Spread | E11: SIMULATED | F11: BULLISH | G11: Price↑(24021.65>23824.1) & EMA9↑(23899.33>23791.89) | H11: 23899.33 | I11: 23791.89 | J11: 2026-06-25 | K11: WEEKLY | L11: 1 | M11: 09:20 IST | N11: 10:51 IST | O11: 24021.65 | P11: 23824.1 | Q11: 24000 CE | R11: 24100 CE | S11: 45 | T11: 65 | U11: 2925 | V11: 16.39 | W11: 11.47 | X11: 47940.75 | Y11: 47995.49 | Z11: 244559.25 | AA11: 14382.23 | AB11: 14382.23 | AC11: -14391 | AD11: -30 | AE11: 40 | AF11: 5.99 | AG11: 0.1 | AH11: 1.44 | AI11: 7.22 | AJ11: 54.74 | AK11: -14445.74 | AL11: STOP LOSS | AM11: 50000 | AN11: PAPER TRADING
A12: 2026-06-25 | B12: NIFTY | C12: Bull Call Spread | D12: Bull Call Spread | E12: SIMULATED | F12: SKIP | G12: Conflicting — Price:BEARISH EMA:BULLISH | H12: 23868.74 | I12: 23768.91 | J12: 2026-06-25 | K12: WEEKLY | L12: 1 | M12: 09:20 IST | N12: 15:03 IST | O12: 23824.1 | P12: 24102.9 | Q12: 23800 CE | R12: 23900 CE | S12: 41 | T12: 65 | U12: 2665 | V12: 17.94 | W12: 18.03 | X12: 47810.1 | Y12: 47864.82 | Z12: 218689.9 | AA12: 14343.03 | AB12: 14343.03 | AC12: 239.85 | AD12: 0.5 | AE12: 40 | AF12: 5.98 | AG12: 0.1 | AH12: 1.43 | AI12: 7.22 | AJ12: 54.72 | AK12: 185.13 | AL12: FLAT | AM12: 50000 | AN12: PAPER TRADING
A13: 2026-06-25 | B13: NIFTY | C13: Bull Call Spread | D13: Bull Call Spread | E13: SIMULATED | F13: BULLISH | G13: Price↑(24056.0>24021.65) & EMA9↑(23930.53>23806.47) | H13: 23930.53 | I13: 23806.47 | J13: 2026-06-25 | K13: WEEKLY | L13: 0 | M13: 09:20 IST | N13: 10:46 IST | O13: 24056 | P13: 24021.65 | Q13: 24000 CE | R13: 24100 CE | S13: 44 | T13: 65 | U13: 2860 | V13: 16.64 | W13: 11.65 | X13: 47590.4 | Y13: 47645.09 | Z13: 238409.6 | AA13: 14277.12 | AB13: 14277.12 | AC13: -14271.4 | AD13: -30 | AE13: 40 | AF13: 5.95 | AG13: 0.1 | AH13: 1.43 | AI13: 7.22 | AJ13: 54.69 | AK13: -14326.09 | AL13: STOP LOSS | AM13: 50000 | AN13: PAPER TRADING
A14: 2026-06-26 | B14: NIFTY | C14: Bull Call Spread | D14: Bull Call Spread | E14: SIMULATED | F14: BULLISH | G14: Price↑(24021.65>23824.1) & EMA9↑(23899.17>23781.51) | H14: 23899.17 | I14: 23781.51 | J14: 2026-06-25 | K14: WEEKLY | L14: 0 | M14: 09:20 IST | N14: 11:00 IST | O14: 24021.65 | P14: 23824.1 | Q14: 24000 CE | R14: 24100 CE | S14: 37 | T14: 65 | U14: 2405 | V14: 19.87 | W14: 25.83 | X14: 47787.35 | Y14: 47842.07 | Z14: 192712.65 | AA14: 14336.2 | AB14: 14336.2 | AC14: 14333.8 | AD14: 30 | AE14: 40 | AF14: 5.97 | AG14: 0.1 | AH14: 1.43 | AI14: 7.22 | AJ14: 54.72 | AK14: 14279.08 | AL14: PROFIT | AM14: 50000 | AN14: PAPER TRADING
A15: 2026-06-26 | B15: NIFTY | C15: Bull Call Spread | D15: Bull Call Spread | E15: SIMULATED | F15: BULLISH | G15: Price↑(24056.0>24021.65) & EMA9↑(23930.98>23794.58) | H15: 23930.98 | I15: 23794.58 | J15: 2026-07-02 | K15: WEEKLY | L15: 6 | M15: 09:20 IST | N15: 11:06 IST | O15: 24056 | P15: 24021.65 | Q15: 24000 CE | R15: 24100 CE | S15: 22 | T15: 65 | U15: 1430 | V15: 33.82 | W15: 23.67 | X15: 48362.6 | Y15: 48417.41 | Z15: 94637.4 | AA15: 14508.78 | AB15: 14508.78 | AC15: -14514.5 | AD15: -30 | AE15: 40 | AF15: 6.05 | AG15: 0.1 | AH15: 1.45 | AI15: 7.22 | AJ15: 54.81 | AK15: -14569.31 | AL15: STOP LOSS | AM15: 50000 | AN15: PAPER TRADING
A16: 2026-06-27 | B16: NIFTY | C16: Bull Call Spread | D16: Bull Call Spread | E16: SIMULATED | F16: BULLISH | G16: Price↑(24056.0>24021.65) & EMA9↑(23930.98>23794.58) | H16: 23930.98 | I16: 23794.58 | J16: 2026-07-02 | K16: WEEKLY | L16: 6 | M16: 09:20 IST | N16: 12:10 IST | O16: 24056 | P16: 24021.65 | Q16: 24000 CE | R16: 24100 CE | S16: 23 | T16: 65 | U16: 1495 | V16: 32.43 | W16: 42.16 | X16: 48482.85 | Y16: 48537.68 | Z16: 101017.15 | AA16: 14544.85 | AB16: 14544.85 | AC16: 14546.35 | AD16: 30 | AE16: 40 | AF16: 6.06 | AG16: 0.1 | AH16: 1.45 | AI16: 7.22 | AJ16: 54.83 | AK16: 14491.52 | AL16: PROFIT | AM16: 50000 | AN16: PAPER TRADING
A17: 2026-06-29 | B17: NIFTY | C17: Bull Call Spread | D17: Bull Call Spread | E17: SIMULATED | F17: SKIP | G17: Conflicting — Price:BEARISH EMA:BULLISH | H17: 23934.65 | I17: 23794.94 | J17: 2026-07-02 | K17: WEEKLY | L17: 3 | M17: 09:20 IST | N17: 10:07 IST | O17: 23946.25 | P17: 24056 | Q17: 23900 CE | R17: 24000 CE | S17: 22 | T17: 65 | U17: 1430 | V17: 34.33 | W17: 24.03 | X17: 49091.9 | Y17: 49146.83 | Z17: 93908.1 | AA17: 14727.57 | AB17: 14727.57 | AC17: -14729 | AD17: -30 | AE17: 40 | AF17: 6.14 | AG17: 0.1 | AH17: 1.47 | AI17: 7.22 | AJ17: 54.93 | AK17: -14783.93 | AL17: STOP LOSS | AM17: 50000 | AN17: PAPER TRADING
A18: 2026-06-30 | B18: NIFTY | C18: Bull Call Spread | D18: Bull Call Spread | E18: SIMULATED | F18: BULLISH | G18: Price↑(24056.0>24021.65) & EMA9↑(23931.75>23779.81) | H18: 23931.75 | I18: 23779.81 | J18: 2026-07-02 | K18: WEEKLY | L18: 3 | M18: 09:20 IST | N18: 09:52 IST | O18: 24056 | P18: 24021.65 | Q18: 24000 CE | R18: 24100 CE | S18: 21 | T18: 65 | U18: 1365 | V18: 34.59 | W18: 44.97 | X18: 47215.35 | Y18: 47269.98 | Z18: 89284.65 | AA18: 14164.6 | AB18: 14164.6 | AC18: 14168.7 | AD18: 30 | AE18: 40 | AF18: 5.9 | AG18: 0.09 | AH18: 1.42 | AI18: 7.22 | AJ18: 54.63 | AK18: 14114.07 | AL18: PROFIT | AM18: 50000 | AN18: PAPER TRADING
A19: 2026-06-30 | B19: NIFTY | C19: Bull Call Spread | D19: Bull Call Spread | E19: SIMULATED | F19: SKIP | G19: Conflicting — Price:BEARISH EMA:BULLISH | H19: 23921.32 | I19: 23787.88 | J19: 2026-07-02 | K19: WEEKLY | L19: 2 | M19: 09:20 IST | N19: 12:08 IST | O19: 23865.75 | P19: 23946.25 | Q19: 23800 CE | R19: 23900 CE | S19: 37 | T19: 65 | U19: 2405 | V19: 20.13 | W19: 26.17 | X19: 48412.65 | Y19: 48467.47 | Z19: 192087.35 | AA19: 14523.8 | AB19: 14523.8 | AC19: 14526.2 | AD19: 30 | AE19: 40 | AF19: 6.05 | AG19: 0.1 | AH19: 1.45 | AI19: 7.22 | AJ19: 54.82 | AK19: 14471.38 | AL19: PROFIT | AM19: 50000 | AN19: PAPER TRADING
A20: 2026-07-01 | B20: NIFTY | C20: Bull Call Spread | D20: Bull Call Spread | E20: SIMULATED | F20: SKIP | G20: Conflicting — Price:BEARISH EMA:BULLISH | H20: 23935.21 | I20: 23780.09 | J20: 2026-07-02 | K20: WEEKLY | L20: 2 | M20: 09:20 IST | N20: 09:56 IST | O20: 23946.25 | P20: 24056 | Q20: 23900 CE | R20: 24000 CE | S20: 48 | T20: 65 | U20: 3120 | V20: 15.17 | W20: 19.72 | X20: 47330.4 | Y20: 47385.05 | Z20: 264669.6 | AA20: 14199.12 | AB20: 14199.12 | AC20: 14196 | AD20: 30 | AE20: 40 | AF20: 5.92 | AG20: 0.09 | AH20: 1.42 | AI20: 7.22 | AJ20: 54.65 | AK20: 14141.35 | AL20: PROFIT | AM20: 50000 | AN20: PAPER TRADING
A21: 2026-07-01 | B21: NIFTY | C21: Bull Call Spread | D21: Bull Call Spread | E21: SIMULATED | F21: BULLISH | G21: Price↑(24005.85>23865.75) & EMA9↑(23938.67>23797.85) | H21: 23938.67 | I21: 23797.85 | J21: 2026-07-02 | K21: WEEKLY | L21: 1 | M21: 09:20 IST | N21: 14:25 IST | O21: 24005.85 | P21: 23865.75 | Q21: 24000 CE | R21: 24100 CE | S21: 33 | T21: 65 | U21: 2145 | V21: 22.04 | W21: 21.2 | X21: 47275.8 | Y21: 47330.44 | Z21: 167224.2 | AA21: 14182.74 | AB21: 14182.74 | AC21: -1801.8 | AD21: -3.8 | AE21: 40 | AF21: 5.91 | AG21: 0.09 | AH21: 1.42 | AI21: 7.22 | AJ21: 54.64 | AK21: -1856.44 | AL21: FLAT | AM21: 50000 | AN21: PAPER TRADING
A22: 2026-07-02 | B22: NIFTY | C22: Bull Call Spread | D22: Bull Call Spread | E22: SIMULATED | F22: SKIP | G22: Conflicting — Price:BEARISH EMA:BULLISH | H22: 23921.87 | I22: 23777.05 | J22: 2026-07-02 | K22: WEEKLY | L22: 1 | M22: 09:20 IST | N22: 12:06 IST | O22: 23865.75 | P22: 23946.25 | Q22: 23800 CE | R22: 23900 CE | S22: 46 | T22: 65 | U22: 2990 | V22: 15.79 | W22: 20.53 | X22: 47212.1 | Y22: 47266.73 | Z22: 251787.9 | AA22: 14163.63 | AB22: 14163.63 | AC22: 14172.6 | AD22: 30 | AE22: 40 | AF22: 5.9 | AG22: 0.09 | AH22: 1.42 | AI22: 7.22 | AJ22: 54.63 | AK22: 14117.97 | AL22: PROFIT | AM22: 50000 | AN22: PAPER TRADING
... A186: 2026-10-29 | B186: NIFTY | C186: Bull Call Spread | D186: Bull Call Spread | E186: SIMULATED | F186: SKIP | G186: Conflicting — Price:BULLISH EMA:BEARISH | H186: 22777.42 | I186: 22825.21 | J186: 2026-10-29 | K186: WEEKLY | L186: 0 | M186: 09:20 IST | N186: 10:01 IST | O186: 22936.75 | P186: 22698.85 | Q186: 22900 CE | R186: 23000 CE | S186: 34 | T186: 65 | U186: 2210 | V186: 21.72 | W186: 28.24 | X186: 48001.2 | Y186: 48055.95 | Z186: 172998.8 | AA186: 14400.36 | AB186: 14400.36 | AC186: 14409.2 | AD186: 30 | AE186: 40 | AF186: 6 | AG186: 0.1 | AH186: 1.44 | AI186: 7.22 | AJ186: 54.75 | AK186: 14354.45 | AL186: PROFIT | AM186: 50000 | AN186: PAPER TRADING

Sheet NIFTY_BearPut
A1: NIFTY — Bear Put Spread | Paper Trading
A2: Date | B2: Instrument | C2: Strategy Mode | D2: Spread | E2: Trend | F2: Trend Reason | G2: EMA 9 | H2: EMA 21 | I2: Expiry | J2: Expiry Type | K2: DTE | L2: Entry Time | M2: Exit Time | N2: Spot at Entry | O2: Prev Close | P2: Buy Strike | Q2: Sell Strike | R2: Lots | S2: Lot Size | T2: Units | U2: Entry Premium | V2: Exit Premium | W2: Total Cost (₹) | X2: Capital Used (₹) | Y2: Max Profit (₹) | Z2: Target (₹) | AA2: Stop Loss (₹) | AB2: Gross P&L (₹) | AC2: Return % | AD2: Brokerage (₹) | AE2: STT (₹) | AF2: SEBI Fee (₹) | AG2: Stamp Duty (₹) | AH2: GST (₹) | AI2: Total Fees (₹) | AJ2: Net P&L (₹) | AK2: Outcome | AL2: Budget (₹) | AM2: Mode
A3: 2026-06-16 | B3: NIFTY | C3: Bear Put Spread | D3: Bear Put Spread | E3: SKIP | F3: Conflicting — Price:BULLISH EMA:BEARISH | G3: 23385.72 | H3: 23538 | I3: 2026-06-18 | J3: WEEKLY | K3: 3 | L3: 09:20 IST | M3: 13:59 IST | N3: 23622.9 | O3: 23161.6 | P3: 23700 PE | Q3: 23600 PE | R3: 17 | S3: 75 | T3: 1275 | U3: 36.99 | V3: 35.75 | W3: 47162.25 | X3: 47216.87 | Y3: 80337.75 | Z3: 14148.67 | AA3: 14148.67 | AB3: -1581 | AC3: -3.4 | AD3: 40 | AE3: 5.9 | AF3: 0.09 | AG3: 1.41 | AH3: 7.22 | AI3: 54.62 | AJ3: -1635.62 | AK3: FLAT | AL3: 50000 | AM3: PAPER TRADING
A4: 2026-06-18 | B4: NIFTY | C4: Bear Put Spread | D4: Bear Put Spread | E4: BULLISH | F4: Price↑(24168.0>24085.7) & EMA9↑(23778.35>23687.38) | G4: 23778.35 | H4: 23687.38 | I4: 2026-06-18 | J4: WEEKLY | K4: 0 | L4: 09:20 IST | M4: 10:22 IST | N4: 24168 | O4: 24085.7 | P4: 24200 PE | Q4: 24100 PE | R4: 26 | S4: 75 | T4: 1950 | U4: 24.91 | V4: 17.44 | W4: 48574.5 | X4: 48629.34 | Y4: 146425.5 | Z4: 14572.35 | AA4: 14572.35 | AB4: -14566.5 | AC4: -30 | AD4: 40 | AE4: 6.07 | AF4: 0.1 | AG4: 1.46 | AH4: 7.22 | AI4: 54.84 | AJ4: -14621.34 | AK4: STOP LOSS | AL4: 50000 | AM4: PAPER TRADING
A5: 2026-06-19 | B5: NIFTY | C5: Bear Put Spread | D5: Bear Put Spread | E5: SKIP | F5: Conflicting — Price:BEARISH EMA:BULLISH | G5: 23824.67 | H5: 23712.22 | I5: 2026-06-25 | J5: WEEKLY | K5: 6 | L5: 09:20 IST | M5: 10:32 IST | N5: 24013.1 | O5: 24168 | P5: 24100 PE | Q5: 24000 PE | R5: 18 | S5: 75 | T5: 1350 | U5: 35.26 | V5: 24.68 | W5: 47601 | X5: 47655.69 | Y5: 87399 | Z5: 14280.3 | AA5: 14280.3 | AB5: -14283 | AC5: -30 | AD5: 40 | AE5: 5.95 | AF5: 0.1 | AG5: 1.43 | AH5: 7.22 | AI5: 54.69 | AJ5: -14337.69 | AK5: STOP LOSS | AL5: 50000 | AM5: PAPER TRADING
A6: 2026-06-20 | B6: NIFTY | C6: Bear Put Spread | D6: Bear Put Spread | E6: BULLISH | F6: Price↑(24168.0>24085.7) & EMA9↑(23777.57>23682.14) | G6: 23777.57 | H6: 23682.14 | I6: 2026-06-25 | J6: WEEKLY | K6: 6 | L6: 09:20 IST | M6: 14:47 IST | N6: 24168 | O6: 24085.7 | P6: 24200 PE | Q6: 24100 PE | R6: 16 | S6: 75 | T6: 1200 | U6: 39.68 | V6: 39.25 | W6: 47616 | X6: 47670.69 | Y6: 72384 | Z6: 14284.8 | AA6: 14284.8 | AB6: -516 | AC6: -1.1 | AD6: 40 | AE6: 5.95 | AF6: 0.1 | AG6: 1.43 | AH6: 7.22 | AI6: 54.69 | AJ6: -570.69 | AK6: FLAT | AL6: 50000 | AM6: PAPER TRADING
A7: 2026-06-23 | B7: NIFTY | C7: Bear Put Spread | D7: Bear Put Spread | E7: SKIP | F7: Conflicting — Price:BEARISH EMA:BULLISH | G7: 23824.22 | H7: 23714.31 | I7: 2026-06-25 | J7: WEEKLY | K7: 3 | L7: 09:20 IST | M7: 10:13 IST | N7: 24013.1 | O7: 24168 | P7: 24100 PE | Q7: 24000 PE | R7: 17 | S7: 75 | T7: 1275 | U7: 38.19 | V7: 49.65 | W7: 48692.25 | X7: 48747.11 | Y7: 78807.75 | Z7: 14607.67 | AA7: 14607.67 | AB7: 14611.5 | AC7: 30 | AD7: 40 | AE7: 6.09 | AF7: 0.1 | AG7: 1.46 | AH7: 7.22 | AI7: 54.86 | AJ7: 14556.64 | AK7: PROFIT | AL7: 50000 | AM7: PAPER TRADING
A8: 2026-06-23 | B8: NIFTY | C8: Bear Put Spread | D8: Bear Put Spread | E8: SKIP | F8: Conflicting — Price:BEARISH EMA:BULLISH | G8: 23824.22 | H8: 23714.31 | I8: 2026-06-25 | J8: WEEKLY | K8: 3 | L8: 09:20 IST | M8: 11:13 IST | N8: 24013.1 | O8: 24168 | P8: 24100 PE | Q8: 24000 PE | R8: 22 | S8: 75 | T8: 1650 | U8: 29.61 | V8: 20.73 | W8: 48856.5 | X8: 48911.39 | Y8: 116143.5 | Z8: 14656.95 | AA8: 14656.95 | AB8: -14652 | AC8: -30 | AD8: 40 | AE8: 6.11 | AF8: 0.1 | AG8: 1.47 | AH8: 7.22 | AI8: 54.89 | AJ8: -14706.89 | AK8: STOP LOSS | AL8: 50000 | AM8: PAPER TRADING
A9: 2026-06-23 | B9: NIFTY | C9: Bear Put Spread | D9: Bear Put Spread | E9: SKIP | F9: Conflicting — Price:BEARISH EMA:BULLISH | G9: 23868.63 | H9: 23767.86 | I9: 2026-06-25 | J9: WEEKLY | K9: 2 | L9: 09:20 IST | M9: 14:28 IST | N9: 23824.1 | O9: 24102.9 | P9: 23900 PE | Q9: 23800 PE | R9: 38 | S9: 75 | T9: 2850 | U9: 16.61 | V9: 17.41 | W9: 47338.5 | X9: 47393.15 | Y9: 237661.5 | Z9: 14201.55 | AA9: 14201.55 | AB9: 2280 | AC9: 4.8 | AD9: 40 | AE9: 5.92 | AF9: 0.09 | AG9: 1.42 | AH9: 7.22 | AI9: 54.65 | AJ9: 2225.35 | AK9: FLAT | AL9: 50000 | AM9: PAPER TRADING
A10: 2026-06-24 | B10: NIFTY | C10: Bear Put Spread | D10: Bear Put Spread | E10: BULLISH | F10: Price↑(24102.9>24013.1) & EMA9↑(23879.76>23762.23) | G10: 23879.76 | H10: 23762.23 | I10: 2026-06-25 | J10: WEEKLY | K10: 2 | L10: 09:20 IST | M10: 10:16 IST | N10: 24102.9 | O10: 24013.1 | P10: 24200 PE | Q10: 24100 PE | R10: 35 | S10: 75 | T10: 2625 | U10: 18.08 | V10: 23.5 | W10: 47460 | X10: 47514.67 | Y10: 215040 | Z10: 14238 | AA10: 14238 | AB10: 14227.5 | AC10: 30 | AD10: 40 | AE10: 5.93 | AF10: 0.09 | AG10: 1.42 | AH10: 7.22 | AI10: 54.67 | AJ10: 14172.83 | AK10: PROFIT | AL10: 50000 | AM10: PAPER TRADING
A11: 2026-06-24 | B11: NIFTY | C11: Bear Put Spread | D11: Bear Put Spread | E11: SIMULATED | F11: BULLISH | G11: Price↑(24021.65>23824.1) & EMA9↑(23899.33>23791.89) | H11: 23899.33 | I11: 23791.89 | J11: 2026-06-25 | K11: WEEKLY | L11: 1 | M11: 09:20 IST | N11: 11:31 IST | O11: 24021.65 | P11: 23824.1 | Q11: 24100 PE | R11: 24000 PE | S11: 37 | T11: 65 | U11: 2405 | V11: 19.72 | W11: 25.64 | X11: 47426.6 | Y11: 47481.26 | Z11: 193073.4 | AA11: 14227.98 | AB11: 14227.98 | AC11: 14237.6 | AD11: 30 | AE11: 40 | AF11: 5.93 | AG11: 0.09 | AH11: 1.42 | AI11: 7.22 | AJ11: 54.66 | AK11: 14182.94 | AL11: PROFIT | AM11: 50000 | AN11: PAPER TRADING
A12: 2026-06-25 | B12: NIFTY | C12: Bear Put Spread | D12: Bear Put Spread | E12: SIMULATED | F12: SKIP | G12: Conflicting — Price:BEARISH EMA:BULLISH | H12: 23868.74 | I12: 23768.91 | J12: 2026-06-25 | K12: WEEKLY | L12: 1 | M12: 09:20 IST | N12: 10:16 IST | O12: 23824.1 | P12: 24102.9 | Q12: 23900 PE | R12: 23800 PE | S12: 32 | T12: 65 | U12: 2080 | V12: 23.06 | W12: 29.98 | X12: 47964.8 | Y12: 48019.55 | Z12: 160035.2 | AA12: 14389.44 | AB12: 14389.44 | AC12: 14393.6 | AD12: 30 | AE12: 40 | AF12: 6 | AG12: 0.1 | AH12: 1.44 | AI12: 7.22 | AJ12: 54.75 | AK12: 14338.85 | AL12: PROFIT | AM12: 50000 | AN12: PAPER TRADING
A13: 2026-06-25 | B13: NIFTY | C13: Bear Put Spread | D13: Bear Put Spread | E13: SIMULATED | F13: BULLISH | G13: Price↑(24056.0>24021.65) & EMA9↑(23930.53>23806.47) | H13: 23930.53 | I13: 23806.47 | J13: 2026-06-25 | K13: WEEKLY | L13: 0 | M13: 09:20 IST | N13: 13:49 IST | O13: 24056 | P13: 24021.65 | Q13: 24100 PE | R13: 24000 PE | S13: 34 | T13: 65 | U13: 2210 | V13: 21.86 | W13: 22.75 | X13: 48310.6 | Y13: 48365.4 | Z13: 172689.4 | AA13: 14493.18 | AB13: 14493.18 | AC13: 1966.9 | AD13: 4.1 | AE13: 40 | AF13: 6.04 | AG13: 0.1 | AH13: 1.45 | AI13: 7.22 | AJ13: 54.8 | AK13: 1912.1 | AL13: FLAT | AM13: 50000 | AN13: PAPER TRADING
A14: 2026-06-26 | B14: NIFTY | C14: Bear Put Spread | D14: Bear Put Spread | E14: SIMULATED | F14: BULLISH | G14: Price↑(24021.65>23824.1) & EMA9↑(23899.17>23781.51) | H14: 23899.17 | I14: 23781.51 | J14: 2026-06-25 | K14: WEEKLY | L14: 0 | M14: 09:20 IST | N14: 09:34 IST | O14: 24021.65 | P14: 23824.1 | Q14: 24100 PE | R14: 24000 PE | S14: 31 | T14: 65 | U14: 2015 | V14: 23.65 | W14: 16.55 | X14: 47654.75 | Y14: 47709.45 | Z14: 153845.25 | AA14: 14296.42 | AB14: 14296.42 | AC14: -14306.5 | AD14: -30 | AE14: 40 | AF14: 5.96 | AG14: 0.1 | AH14: 1.43 | AI14: 7.22 | AJ14: 54.7 | AK14: -14361.2 | AL14: STOP LOSS | AM14: 50000 | AN14: PAPER TRADING
A15: 2026-06-26 | B15: NIFTY | C15: Bear Put Spread | D15: Bear Put Spread | E15: SIMULATED | F15: BULLISH | G15: Price↑(24056.0>24021.65) & EMA9↑(23930.98>23794.58) | H15: 23930.98 | I15: 23794.58 | J15: 2026-07-02 | K15: WEEKLY | L15: 6 | M15: 09:20 IST | N15: 10:15 IST | O15: 24056 | P15: 24021.65 | Q15: 24100 PE | R15: 24000 PE | S15: 23 | T15: 65 | U15: 1495 | V15: 32.73 | W15: 42.55 | X15: 48931.35 | Y15: 48986.25 | Z15: 100568.65 | AA15: 14679.4 | AB15: 14679.4 | AC15: 14680.9 | AD15: 30 | AE15: 40 | AF15: 6.12 | AG15: 0.1 | AH15: 1.47 | AI15: 7.22 | AJ15: 54.9 | AK15: 14626 | AL15: PROFIT | AM15: 50000 | AN15: PAPER TRADING
A16: 2026-06-27 | B16: NIFTY | C16: Bear Put Spread | D16: Bear Put Spread | E16: SIMULATED | F16: BULLISH | G16: Price↑(24056.0>24021.65) & EMA9↑(23930.98>23794.58) | H16: 23930.98 | I16: 23794.58 | J16: 2026-07-02 | K16: WEEKLY | L16: 6 | M16: 09:20 IST | N16: 10:51 IST | O16: 24056 | P16: 24021.65 | Q16: 24100 PE | R16: 24000 PE | S16: 28 | T16: 65 | U16: 1820 | V16: 26.4 | W16: 34.32 | X16: 48048 | Y16: 48102.76 | Z16: 133952 | AA16: 14414.4 | AB16: 14414.4 | AC16: 14414.4 | AD16: 30 | AE16: 40 | AF16: 6.01 | AG16: 0.1 | AH16: 1.44 | AI16: 7.22 | AJ16: 54.76 | AK16: 14359.64 | AL16: PROFIT | AM16: 50000 | AN16: PAPER TRADING
A17: 2026-06-29 | B17: NIFTY | C17: Bear Put Spread | D17: Bear Put Spread | E17: SIMULATED | F17: SKIP | G17: Conflicting — Price:BEARISH EMA:BULLISH | H17: 23934.65 | I17: 23794.94 | J17: 2026-07-02 | K17: WEEKLY | L17: 3 | M17: 09:20 IST | N17: 10:17 IST | O17: 23946.25 | P17: 24056 | Q17: 24000 PE | R17: 23900 PE | S17: 25 | T17: 65 | U17: 1625 | V17: 29.15 | W17: 20.4 | X17: 47368.75 | Y17: 47423.4 | Z17: 115131.25 | AA17: 14210.62 | AB17: 14210.62 | AC17: -14218.75 | AD17: -30 | AE17: 40 | AF17: 5.92 | AG17: 0.09 | AH17: 1.42 | AI17: 7.22 | AJ17: 54.65 | AK17: -14273.4 | AL17: STOP LOSS | AM17: 50000 | AN17: PAPER TRADING
A18: 2026-06-30 | B18: NIFTY | C18: Bear Put Spread | D18: Bear Put Spread | E18: SIMULATED | F18: BULLISH | G18: Price↑(24056.0>24021.65) & EMA9↑(23931.75>23779.81) | H18: 23931.75 | I18: 23779.81 | J18: 2026-07-02 | K18: WEEKLY | L18: 3 | M18: 09:20 IST | N18: 10:55 IST | O18: 24056 | P18: 24021.65 | Q18: 24100 PE | R18: 24000 PE | S18: 19 | T18: 65 | U18: 1235 | V18: 38.8 | W18: 27.16 | X18: 47918 | Y18: 47972.74 | Z18: 75582 | AA18: 14375.4 | AB18: 14375.4 | AC18: -14375.4 | AD18: -30 | AE18: 40 | AF18: 5.99 | AG18: 0.1 | AH18: 1.44 | AI18: 7.22 | AJ18: 54.74 | AK18: -14430.14 | AL18: STOP LOSS | AM18: 50000 | AN18: PAPER TRADING
A19: 2026-06-30 | B19: NIFTY | C19: Bear Put Spread | D19: Bear Put Spread | E19: SIMULATED | F19: SKIP | G19: Conflicting — Price:BEARISH EMA:BULLISH | H19: 23921.32 | I19: 23787.88 | J19: 2026-07-02 | K19: WEEKLY | L19: 2 | M19: 09:20 IST | N19: 11:18 IST | O19: 23865.75 | P19: 23946.25 | Q19: 23900 PE | R19: 23800 PE | S19: 33 | T19: 65 | U19: 2145 | V19: 22.56 | W19: 15.79 | X19: 48391.2 | Y19: 48446.01 | Z19: 166108.8 | AA19: 14517.36 | AB19: 14517.36 | AC19: -14521.65 | AD19: -30 | AE19: 40 | AF19: 6.05 | AG19: 0.1 | AH19: 1.45 | AI19: 7.22 | AJ19: 54.81 | AK19: -14576.46 | AL19: STOP LOSS | AM19: 50000 | AN19: PAPER TRADING
A20: 2026-07-01 | B20: NIFTY | C20: Bear Put Spread | D20: Bear Put Spread | E20: SIMULATED | F20: SKIP | G20: Conflicting — Price:BEARISH EMA:BULLISH | H20: 23935.21 | I20: 23780.09 | J20: 2026-07-02 | K20: WEEKLY | L20: 2 | M20: 09:20 IST | N20: 12:16 IST | O20: 23946.25 | P20: 24056 | Q20: 24000 PE | R20: 23900 PE | S20: 31 | T20: 65 | U20: 2015 | V20: 23.9 | W20: 31.07 | X20: 48158.5 | Y20: 48213.28 | Z20: 153341.5 | AA20: 14447.55 | AB20: 14447.55 | AC20: 14447.55 | AD20: 30 | AE20: 40 | AF20: 6.02 | AG20: 0.1 | AH20: 1.44 | AI20: 7.22 | AJ20: 54.78 | AK20: 14392.77 | AL20: PROFIT | AM20: 50000 | AN20: PAPER TRADING
A21: 2026-07-01 | B21: NIFTY | C21: Bear Put Spread | D21: Bear Put Spread | E21: SIMULATED | F21: BULLISH | G21: Price↑(24005.85>23865.75) & EMA9↑(23938.67>23797.85) | H21: 23938.67 | I21: 23797.85 | J21: 2026-07-02 | K21: WEEKLY | L21: 1 | M21: 09:20 IST | N21: 09:58 IST | O21: 24005.85 | P21: 23865.75 | Q21: 24100 PE | R21: 24000 PE | S21: 30 | T21: 65 | U21: 1950 | V21: 24.98 | W21: 32.47 | X21: 48711 | Y21: 48765.87 | Z21: 146289 | AA21: 14613.3 | AB21: 14613.3 | AC21: 14605.5 | AD21: 30 | AE21: 40 | AF21: 6.09 | AG21: 0.1 | AH21: 1.46 | AI21: 7.22 | AJ21: 54.87 | AK21: 14550.63 | AL21: PROFIT | AM21: 50000 | AN21: PAPER TRADING
A22: 2026-07-02 | B22: NIFTY | C22: Bear Put Spread | D22: Bear Put Spread | E22: SIMULATED | F22: SKIP | G22: Conflicting — Price:BEARISH EMA:BULLISH | H22: 23921.87 | I22: 23777.05 | J22: 2026-07-02 | K22: WEEKLY | L22: 1 | M22: 09:20 IST | N22: 10:53 IST | O22: 23865.75 | P22: 23946.25 | Q22: 23900 PE | R22: 23800 PE | S22: 32 | T22: 65 | U22: 2080 | V22: 23.18 | W22: 30.13 | X22: 48214.4 | Y22: 48269.19 | Z22: 159785.6 | AA22: 14464.32 | AB22: 14464.32 | AC22: 14456 | AD22: 30 | AE22: 40 | AF22: 6.03 | AG22: 0.1 | AH22: 1.45 | AI22: 7.22 | AJ22: 54.79 | AK22: 14401.21 | AL22: PROFIT | AM22: 50000 | AN22: PAPER TRADING
... A186: 2026-10-29 | B186: NIFTY | C186: Bear Put Spread | D186: Bear Put Spread | E186: SIMULATED | F186: SKIP | G186: Conflicting — Price:BULLISH EMA:BEARISH | H186: 22777.42 | I186: 22825.21 | J186: 2026-10-29 | K186: WEEKLY | L186: 0 | M186: 09:20 IST | N186: 11:58 IST | O186: 22936.75 | P186: 22698.85 | Q186: 23000 PE | R186: 22900 PE | S186: 42 | T186: 65 | U186: 2730 | V186: 17.39 | W186: 22.61 | X186: 47474.7 | Y186: 47529.37 | Z186: 225525.3 | AA186: 14242.41 | AB186: 14242.41 | AC186: 14250.6 | AD186: 30 | AE186: 40 | AF186: 5.93 | AG186: 0.09 | AH186: 1.42 | AI186: 7.22 | AJ186: 54.67 | AK186: 14195.93 | AL186: PROFIT | AM186: 50000 | AN186: PAPER TRADING

Sheet NIFTY_Both
A1: NIFTY — Both Spreads | Paper Trading
A2: Date | B2: Instrument | C2: Strategy Mode | D2: Spread | E2: Trend | F2: Trend Reason | G2: EMA 9 | H2: EMA 21 | I2: Expiry | J2: Expiry Type | K2: DTE | L2: Entry Time | M2: Exit Time | N2: Spot at Entry | O2: Prev Close | P2: Buy Strike | Q2: Sell Strike | R2: Lots | S2: Lot Size | T2: Units | U2: Entry Premium | V2: Exit Premium | W2: Total Cost (₹) | X2: Capital Used (₹) | Y2: Max Profit (₹) | Z2: Target (₹) | AA2: Stop Loss (₹) | AB2: Gross P&L (₹) | AC2: Return % | AD2: Brokerage (₹) | AE2: STT (₹) | AF2: SEBI Fee (₹) | AG2: Stamp Duty (₹) | AH2: GST (₹) | AI2: Total Fees (₹) | AJ2: Net P&L (₹) | AK2: Outcome | AL2: Budget (₹) | AM2: Mode
A3: 2026-06-16 | B3: NIFTY | C3: Both Spreads | D3: Bull Call Spread | E3: SKIP | F3: Conflicting — Price:BULLISH EMA:BEARISH | G3: 23385.72 | H3: 23538 | I3: 2026-06-18 | J3: WEEKLY | K3: 3 | L3: 09:20 IST | M3: 11:48 IST | N3: 23622.9 | O3: 23161.6 | P3: 23600 CE | Q3: 23700 CE | R3: 16 | S3: 75 | T3: 1200 | U3: 38.73 | V3: 50.35 | W3: 46476 | X3: 46530.51 | Y3: 73524 | Z3: 13942.8 | AA3: 13942.8 | AB3: 13944 | AC3: 30 | AD3: 40 | AE3: 5.81 | AF3: 0.09 | AG3: 1.39 | AH3: 7.22 | AI3: 54.51 | AJ3: 13889.49 | AK3: PROFIT | AL3: 50000 | AM3: PAPER TRADING
A4: 2026-06-16 | B4: NIFTY | C4: Both Spreads | D4: Bear Put Spread | E4: SKIP | F4: Conflicting — Price:BULLISH EMA:BEARISH | G4: 23385.72 | H4: 23538 | I4: 2026-06-18 | J4: WEEKLY | K4: 3 | L4: 09:20 IST | M4: 11:13 IST | N4: 23622.9 | O4: 23161.6 | P4: 23700 PE | Q4: 23600 PE | R4: 25 | S4: 75 | T4: 1875 | U4: 25.78 | V4: 18.05 | W4: 48337.5 | X4: 48392.31 | Y4: 139162.5 | Z4: 14501.25 | AA4: 14501.25 | AB4: -14493.75 | AC4: -30 | AD4: 40 | AE4: 6.04 | AF4: 0.1 | AG4: 1.45 | AH4: 7.22 | AI4: 54.81 | AJ4: -14548.56 | AK4: STOP LOSS | AL4: 50000 | AM4: PAPER TRADING
A5: 2026-06-18 | B5: NIFTY | C5: Both Spreads | D5: Bull Call Spread | E5: BULLISH | F5: Price↑(24168.0>24085.7) & EMA9↑(23778.35>23687.38) | G5: 23778.35 | H5: 23687.38 | I5: 2026-06-18 | J5: WEEKLY | K5: 0 | L5: 09:20 IST | M5: 09:54 IST | N5: 24168 | O5: 24085.7 | P5: 24100 CE | Q5: 24200 CE | R5: 30 | S5: 75 | T5: 2250 | U5: 21.55 | V5: 28.02 | W5: 48487.5 | X5: 48542.33 | Y5: 176512.5 | Z5: 14546.25 | AA5: 14546.25 | AB5: 14557.5 | AC5: 30 | AD5: 40 | AE5: 6.06 | AF5: 0.1 | AG5: 1.45 | AH5: 7.22 | AI5: 54.83 | AJ5: 14502.67 | AK5: PROFIT | AL5: 50000 | AM5: PAPER TRADING
A6: 2026-06-18 | B6: NIFTY | C6: Both Spreads | D6: Bear Put Spread | E6: BULLISH | F6: Price↑(24168.0>24085.7) & EMA9↑(23778.35>23687.38) | G6: 23778.35 | H6: 23687.38 | I6: 2026-06-18 | J6: WEEKLY | K6: 0 | L6: 09:20 IST | M6: 10:35 IST | N6: 24168 | O6: 24085.7 | P6: 24200 PE | Q6: 24100 PE | R6: 37 | S6: 75 | T6: 2775 | U6: 17.44 | V6: 12.21 | W6: 48396 | X6: 48450.82 | Y6: 229104 | Z6: 14518.8 | AA6: 14518.8 | AB6: -14513.25 | AC6: -30 | AD6: 40 | AE6: 6.05 | AF6: 0.1 | AG6: 1.45 | AH6: 7.22 | AI6: 54.82 | AJ6: -14568.07 | AK6: STOP LOSS | AL6: 50000 | AM6: PAPER TRADING
A7: 2026-06-19 | B7: NIFTY | C7: Both Spreads | D7: Bull Call Spread | E7: SKIP | F7: Conflicting — Price:BEARISH EMA:BULLISH | G7: 23824.67 | H7: 23712.22 | I7: 2026-06-25 | J7: WEEKLY | K7: 6 | L7: 09:20 IST | M7: 12:16 IST | N7: 24013.1 | O7: 24168 | P7: 24000 CE | Q7: 24100 CE | R7: 25 | S7: 75 | T7: 1875 | U7: 25.32 | V7: 32.92 | W7: 47475 | X7: 47529.67 | Y7: 140025 | Z7: 14242.5 | AA7: 14242.5 | AB7: 14250 | AC7: 30 | AD7: 40 | AE7: 5.93 | AF7: 0.09 | AG7: 1.42 | AH7: 7.22 | AI7: 54.67 | AJ7: 14195.33 | AK7: PROFIT | AL7: 50000 | AM7: PAPER TRADING
A8: 2026-06-19 | B8: NIFTY | C8: Both Spreads | D8: Bear Put Spread | E8: SKIP | F8: Conflicting — Price:BEARISH EMA:BULLISH | G8: 23824.67 | H8: 23712.22 | I8: 2026-06-25 | J8: WEEKLY | K8: 6 | L8: 09:20 IST | M8: 09:54 IST | N8: 24013.1 | O8: 24168 | P8: 24100 PE | Q8: 24000 PE | R8: 19 | S8: 75 | T8: 1425 | U8: 33.62 | V8: 43.71 | W8: 47908.5 | X8: 47963.24 | Y8: 94591.5 | Z8: 14372.55 | AA8: 14372.55 | AB8: 14378.25 | AC8: 30 | AD8: 40 | AE8: 5.99 | AF8: 0.1 | AG8: 1.44 | AH8: 7.22 | AI8: 54.74 | AJ8: 14323.51 | AK8: PROFIT | AL8: 50000 | AM8: PAPER TRADING
A9: 2026-06-20 | B9: NIFTY | C9: Both Spreads | D9: Bull Call Spread | E9: BULLISH | F9: Price↑(24168.0>24085.7) & EMA9↑(23777.57>23682.14) | G9: 23777.57 | H9: 23682.14 | I9: 2026-06-25 | J9: WEEKLY | K9: 6 | L9: 09:20 IST | M9: 09:58 IST | N9: 24168 | O9: 24085.7 | P9: 24100 CE | Q9: 24200 CE | R9: 25 | S9: 75 | T9: 1875 | U9: 25.29 | V9: 17.7 | W9: 47418.75 | X9: 47473.41 | Y9: 140081.25 | Z9: 14225.62 | AA9: 14225.62 | AB9: -14231.25 | AC9: -30 | AD9: 40 | AE9: 5.93 | AF9: 0.09 | AG9: 1.42 | AH9: 7.22 | AI9: 54.66 | AJ9: -14285.91 | AK9: STOP LOSS | AL9: 50000 | AM9: PAPER TRADING
A10: 2026-06-20 | B10: NIFTY | C10: Both Spreads | D10: Bear Put Spread | E10: BULLISH | F10: Price↑(24168.0>24085.7) & EMA9↑(23777.57>23682.14) | G10: 23777.57 | H10: 23682.14 | I10: 2026-06-25 | J10: WEEKLY | K10: 6 | L10: 09:20 IST | M10: 10:08 IST | N10: 24168 | O10: 24085.7 | P10: 24200 PE | Q10: 24100 PE | R10: 17 | S10: 75 | T10: 1275 | U10: 38.16 | V10: 49.61 | W10: 48654 | X10: 48708.86 | Y10: 78846 | Z10: 14596.2 | AA10: 14596.2 | AB10: 14598.75 | AC10: 30 | AD10: 40 | AE10: 6.08 | AF10: 0.1 | AG10: 1.46 | AH10: 7.22 | AI10: 54.86 | AJ10: 14543.89 | AK10: PROFIT | AL10: 50000 | AM10: PAPER TRADING
A11: 2026-06-23 | B11: NIFTY | C11: Both Spreads | D11: Bull Call Spread | E11: SKIP | F11: Conflicting — Price:BEARISH EMA:BULLISH | G11: 23824.22 | H11: 23714.31 | I11: 2026-06-25 | J11: WEEKLY | K11: 3 | L11: 09:20 IST | M11: 09:51 IST | N11: 24013.1 | O11: 24168 | P11: 24000 CE | Q11: 24100 CE | R11: 18 | S11: 75 | T11: 1350 | U11: 35 | V11: 24.5 | W11: 47250 | X11: 47304.64 | Y11: 87750 | Z11: 14175 | AA11: 14175 | AB11: -14175 | AC11: -30 | AD11: 40 | AE11: 5.91 | AF11: 0.09 | AG11: 1.42 | AH11: 7.22 | AI11: 54.64 | AJ11: -14229.64 | AK11: STOP LOSS | AL11: 50000 | AM11: PAPER TRADING
A12: 2026-06-23 | B12: NIFTY | C12: Both Spreads | D12: Bear Put Spread | E12: SKIP | F12: Conflicting — Price:BEARISH EMA:BULLISH | G12: 23824.22 | H12: 23714.31 | I12: 2026-06-25 | J12: WEEKLY | K12: 3 | L12: 09:20 IST | M12: 10:07 IST | N12: 24013.1 | O12: 24168 | P12: 24100 PE | Q12: 24000 PE | R12: 17 | S12: 75 | T12: 1275 | U12: 37.94 | V12: 49.32 | W12: 48373.5 | X12: 48428.31 | Y12: 79126.5 | Z12: 14512.05 | AA12: 14512.05 | AB12: 14509.5 | AC12: 30 | AD12: 40 | AE12: 6.05 | AF12: 0.1 | AG12: 1.45 | AH12: 7.22 | AI12: 54.81 | AJ12: 14454.69 | AK12: PROFIT | AL12: 50000 | AM12: PAPER TRADING
A13: 2026-06-23 | B13: NIFTY | C13: Both Spreads | D13: Bull Call Spread | E13: SKIP | F13: Conflicting — Price:BEARISH EMA:BULLISH | G13: 23824.22 | H13: 23714.31 | I13: 2026-06-25 | J13: WEEKLY | K13: 3 | L13: 09:20 IST | M13: 11:33 IST | N13: 24013.1 | O13: 24168 | P13: 24000 CE | Q13: 24100 CE | R13: 20 | S13: 75 | T13: 1500 | U13: 32.72 | V13: 42.54 | W13: 49080 | X13: 49134.92 | Y13: 100920 | Z13: 14724 | AA13: 14724 | AB13: 14730 | AC13: 30 | AD13: 40 | AE13: 6.13 | AF13: 0.1 | AG13: 1.47 | AH13: 7.22 | AI13: 54.92 | AJ13: 14675.08 | AK13: PROFIT | AL13: 50000 | AM13: PAPER TRADING
A14: 2026-06-23 | B14: NIFTY | C14: Both Spreads | D14: Bear Put Spread | E14: SKIP | F14: Conflicting — Price:BEARISH EMA:BULLISH | G14: 23824.22 | H14: 23714.31 | I14: 2026-06-25 | J14: WEEKLY | K14: 3 | L14: 09:20 IST | M14: 09:34 IST | N14: 24013.1 | O14: 24168 | P14: 24100 PE | Q14: 24000 PE | R14: 21 | S14: 75 | T14: 1575 | U14: 30.41 | V14: 21.29 | W14: 47895.75 | X14: 47950.49 | Y14: 109604.25 | Z14: 14368.73 | AA14: 14368.73 | AB14: -14364 | AC14: -30 | AD14: 40 | AE14: 5.99 | AF14: 0.1 | AG14: 1.44 | AH14: 7.22 | AI14: 54.74 | AJ14: -14418.74 | AK14: STOP LOSS | AL14: 50000 | AM14: PAPER TRADING
... A18: 2026-06-24 | B18: NIFTY | C18: Both Spreads | D18: Bear Put Spread | E18: BULLISH | F18: Price↑(24102.9>24013.1) & EMA9↑(23879.76>23762.23) | G18: 23879.76 | H18: 23762.23 | I18: 2026-06-25 | J18: WEEKLY | K18: 2 | L18: 09:20 IST | M18: 11:50 IST | N18: 24102.9 | O18: 24013.1 | P18: 24200 PE | Q18: 24100 PE | R18: 28 | S18: 75 | T18: 2100 | U18: 22.82 | V18: 29.67 | W18: 47922 | X18: 47976.74 | Y18: 162078 | Z18: 14376.6 | AA18: 14376.6 | AB18: 14385 | AC18: 30 | AD18: 40 | AE18: 5.99 | AF18: 0.1 | AG18: 1.44 | AH18: 7.22 | AI18: 54.74 | AJ18: 14330.26 | AK18: PROFIT | AL18: 50000 | AM18: PAPER TRADING
A19: 2026-06-24 | B19: NIFTY | C19: Both Spreads | D19: Bull Call Spread | E19: SIMULATED | F19: BULLISH | G19: Price↑(24021.65>23824.1) & EMA9↑(23899.33>23791.89) | H19: 23899.33 | I19: 23791.89 | J19: 2026-06-25 | K19: WEEKLY | L19: 1 | M19: 09:20 IST | N19: 10:09 IST | O19: 24021.65 | P19: 23824.1 | Q19: 24000 CE | R19: 24100 CE | S19: 44 | T19: 65 | U19: 2860 | V19: 16.56 | W19: 21.53 | X19: 47361.6 | Y19: 47416.25 | Z19: 238638.4 | AA19: 14208.48 | AB19: 14208.48 | AC19: 14214.2 | AD19: 30 | AE19: 40 | AF19: 5.92 | AG19: 0.09 | AH19: 1.42 | AI19: 7.22 | AJ19: 54.65 | AK19: 14159.55 | AL19: PROFIT | AM19: 50000 | AN19: PAPER TRADING
A20: 2026-06-24 | B20: NIFTY | C20: Both Spreads | D20: Bear Put Spread | E20: SIMULATED | F20: BULLISH | G20: Price↑(24021.65>23824.1) & EMA9↑(23899.33>23791.89) | H20: 23899.33 | I20: 23791.89 | J20: 2026-06-25 | K20: WEEKLY | L20: 1 | M20: 09:20 IST | N20: 11:13 IST | O20: 24021.65 | P20: 23824.1 | Q20: 24100 PE | R20: 24000 PE | S20: 34 | T20: 65 | U20: 2210 | V20: 21.58 | W20: 28.05 | X20: 47691.8 | Y20: 47746.5 | Z20: 173308.2 | AA20: 14307.54 | AB20: 14307.54 | AC20: 14298.7 | AD20: 30 | AE20: 40 | AF20: 5.96 | AG20: 0.1 | AH20: 1.43 | AI20: 7.22 | AJ20: 54.7 | AK20: 14244 | AL20: PROFIT | AM20: 50000 | AN20: PAPER TRADING
A21: 2026-06-25 | B21: NIFTY | C21: Both Spreads | D21: Bull Call Spread | E21: SIMULATED | F21: SKIP | G21: Conflicting — Price:BEARISH EMA:BULLISH | H21: 23868.74 | I21: 23768.91 | J21: 2026-06-25 | K21: WEEKLY | L21: 1 | M21: 09:20 IST | N21: 10:44 IST | O21: 23824.1 | P21: 24102.9 | Q21: 23800 CE | R21: 23900 CE | S21: 37 | T21: 65 | U21: 2405 | V21: 19.99 | W21: 13.99 | X21: 48075.95 | Y21: 48130.72 | Z21: 192424.05 | AA21: 14422.78 | AB21: 14422.78 | AC21: -14430 | AD21: -30 | AE21: 40 | AF21: 6.01 | AG21: 0.1 | AH21: 1.44 | AI21: 7.22 | AJ21: 54.77 | AK21: -14484.77 | AL21: STOP LOSS | AM21: 50000 | AN21: PAPER TRADING
A22: 2026-06-25 | B22: NIFTY | C22: Both Spreads | D22: Bear Put Spread | E22: SIMULATED | F22: SKIP | G22: Conflicting — Price:BEARISH EMA:BULLISH | H22: 23868.74 | I22: 23768.91 | J22: 2026-06-25 | K22: WEEKLY | L22: 1 | M22: 09:20 IST | N22: 14:59 IST | O22: 23824.1 | P22: 24102.9 | Q22: 23900 PE | R22: 23800 PE | S22: 43 | T22: 65 | U22: 2795 | V22: 17.2 | W22: 16.93 | X22: 48074 | Y22: 48128.76 | Z22: 231426 | AA22: 14422.2 | AB22: 14422.2 | AC22: -754.65 | AD22: -1.6 | AE22: 40 | AF22: 6.01 | AG22: 0.1 | AH22: 1.44 | AI22: 7.22 | AJ22: 54.76 | AK22: -809.41 | AL22: FLAT | AM22: 50000 | AN22: PAPER TRADING
A23: 2026-06-25 | B23: NIFTY | C23: Both Spreads | D23: Bull Call Spread | E23: SIMULATED | F23: BULLISH | G23: Price↑(24056.0>24021.65) & EMA9↑(23930.53>23806.47) | H23: 23930.53 | I23: 23806.47 | J23: 2026-06-25 | K23: WEEKLY | L23: 0 | M23: 09:20 IST | N23: 11:50 IST | O23: 24056 | P23: 24021.65 | Q23: 24000 CE | R23: 24100 CE | S23: 41 | T23: 65 | U23: 2665 | V23: 18.05 | W23: 23.47 | X23: 48103.25 | Y23: 48158.02 | Z23: 218396.75 | AA23: 14430.98 | AB23: 14430.98 | AC23: 14444.3 | AD23: 30 | AE23: 40 | AF23: 6.01 | AG23: 0.1 | AH23: 1.44 | AI23: 7.22 | AJ23: 54.77 | AK23: 14389.53 | AL23: PROFIT | AM23: 50000 | AN23: PAPER TRADING
A24: 2026-06-25 | B24: NIFTY | C24: Both Spreads | D24: Bear Put Spread | E24: SIMULATED | F24: BULLISH | G24: Price↑(24056.0>24021.65) & EMA9↑(23930.53>23806.47) | H24: 23930.53 | I24: 23806.47 | J24: 2026-06-25 | K24: WEEKLY | L24: 0 | M24: 09:20 IST | N24: 11:04 IST | O24: 24056 | P24: 24021.65 | Q24: 24100 PE | R24: 24000 PE | S24: 41 | T24: 65 | U24: 2665 | V24: 17.8 | W24: 23.14 | X24: 47437 | Y24: 47491.66 | Z24: 219063 | AA24: 14231.1 | AB24: 14231.1 | AC24: 14231.1 | AD24: 30 | AE24: 40 | AF24: 5.93 | AG24: 0.09 | AH24: 1.42 | AI24: 7.22 | AJ24: 54.66 | AK24: 14176.44 | AL24: PROFIT | AM24: 50000 | AN24: PAPER TRADING
A25: 2026-06-26 | B25: NIFTY | C25: Both Spreads | D25: Bull Call Spread | E25: SIMULATED | F25: BULLISH | G25: Price↑(24021.65>23824.1) & EMA9↑(23899.17>23781.51) | H25: 23899.17 | I25: 23781.51 | J25: 2026-06-25 | K25: WEEKLY | L25: 0 | M25: 09:20 IST | N25: 11:42 IST | O25: 24021.65 | P25: 23824.1 | Q25: 24000 CE | R25: 24100 CE | S25: 31 | T25: 65 | U25: 2015 | V25: 24.16 | W25: 31.41 | X25: 48682.4 | Y25: 48737.26 | Z25: 152817.6 | AA25: 14604.72 | AB25: 14604.72 | AC25: 14608.75 | AD25: 30 | AE25: 40 | AF25: 6.09 | AG25: 0.1 | AH25: 1.46 | AI25: 7.22 | AJ25: 54.86 | AK25: 14553.89 | AL25: PROFIT | AM25: 50000 | AN25: PAPER TRADING
A26: 2026-06-26 | B26: NIFTY | C26: Both Spreads | D26: Bear Put Spread | E26: SIMULATED | F26: BULLISH | G26: Price↑(24021.65>23824.1) & EMA9↑(23899.17>23781.51) | H26: 23899.17 | I26: 23781.51 | J26: 2026-06-25 | K26: WEEKLY | L26: 0 | M26: 09:20 IST | N26: 09:57 IST | O26: 24021.65 | P26: 23824.1 | Q26: 24100 PE | R26: 24000 PE | S26: 35 | T26: 65 | U26: 2275 | V26: 20.83 | W26: 27.08 | X26: 47388.25 | Y26: 47442.91 | Z26: 180111.75 | AA26: 14216.48 | AB26: 14216.48 | AC26: 14218.75 | AD26: 30 | AE26: 40 | AF26: 5.92 | AG26: 0.09 | AH26: 1.42 | AI26: 7.22 | AJ26: 54.66 | AK26: 14164.09 | AL26: PROFIT | AM26: 50000 | AN26: PAPER TRADING
A27: 2026-06-26 | B27: NIFTY | C27: Both Spreads | D27: Bull Call Spread | E27: SIMULATED | F27: BULLISH | G27: Price↑(24056.0>24021.65) & EMA9↑(23930.98>23794.58) | H27: 23930.98 | I27: 23794.58 | J27: 2026-07-02 | K27: WEEKLY | L27: 6 | M27: 09:20 IST | N27: 09:58 IST | O27: 24056 | P27: 24021.65 | Q27: 24000 CE | R27: 24100 CE | S27: 21 | T27: 65 | U27: 1365 | V27: 34.45 | W27: 24.12 | X27: 47024.25 | Y27: 47078.85 | Z27: 89475.75 | AA27: 14107.27 | AB27: 14107.27 | AC27: -14100.45 | AD27: -30 | AE27: 40 | AF27: 5.88 | AG27: 0.09 | AH27: 1.41 | AI27: 7.22 | AJ27: 54.6 | AK27: -14155.05 | AL27: STOP LOSS | AM27: 50000 | AN27: PAPER TRADING
A28: 2026-06-26 | B28: NIFTY | C28: Both Spreads | D28: Bear Put Spread | E28: SIMULATED | F28: BULLISH | G28: Price↑(24056.0>24021.65) & EMA9↑(23930.98>23794.58) | H28: 23930.98 | I28: 23794.58 | J28: 2026-07-02 | K28: WEEKLY | L28: 6 | M28: 09:20 IST | N28: 10:22 IST | O28: 24056 | P28: 24021.65 | Q28: 24100 PE | R28: 24000 PE | S28: 22 | T28: 65 | U28: 1430 | V28: 33.09 | W28: 43.02 | X28: 47318.7 | Y28: 47373.35 | Z28: 95681.3 | AA28: 14195.61 | AB28: 14195.61 | AC28: 14199.9 | AD28: 30 | AE28: 40 | AF28: 5.91 | AG28: 0.09 | AH28: 1.42 | AI28: 7.22 | AJ28: 54.65 | AK28: 14145.25 | AL28: PROFIT | AM28: 50000 | AN28: PAPER TRADING
A29: 2026-06-27 | B29: NIFTY | C29: Both Spreads | D29: Bull Call Spread | E29: SIMULATED | F29: BULLISH | G29: Price↑(24056.0>24021.65) & EMA9↑(23930.98>23794.58) | H29: 23930.98 | I29: 23794.58 | J29: 2026-07-02 | K29: WEEKLY | L29: 6 | M29: 09:20 IST | N29: 10:09 IST | O29: 24056 | P29: 24021.65 | Q29: 24000 CE | R29: 24100 CE | S29: 19 | T29: 65 | U29: 1235 | V29: 39.59 | W29: 51.47 | X29: 48893.65 | Y29: 48948.54 | Z29: 74606.35 | AA29: 14668.09 | AB29: 14668.09 | AC29: 14671.8 | AD29: 30 | AE29: 40 | AF29: 6.11 | AG29: 0.1 | AH29: 1.47 | AI29: 7.22 | AJ29: 54.89 | AK29: 14616.91 | AL29: PROFIT | AM29: 50000 | AN29: PAPER TRADING
A30: 2026-06-27 | B30: NIFTY | C30: Both Spreads | D30: Bear Put Spread | E30: SIMULATED | F30: BULLISH | G30: Price↑(24056.0>24021.65) & EMA9↑(23930.98>23794.58) | H30: 23930.98 | I30: 23794.58 | J30: 2026-07-02 | K30: WEEKLY | L30: 6 | M30: 09:20 IST | N30: 11:12 IST | O30: 24056 | P30: 24021.65 | Q30: 24100 PE | R30: 24000 PE | S30: 21 | T30: 65 | U30: 1365 | V30: 35.93 | W30: 46.71 | X30: 49044.45 | Y30: 49099.37 | Z30: 87455.55 | AA30: 14713.33 | AB30: 14713.33 | AC30: 14714.7 | AD30: 30 | AE30: 40 | AF30: 6.13 | AG30: 0.1 | AH30: 1.47 | AI30: 7.22 | AJ30: 54.92 | AK30: 14659.78 | AL30: PROFIT | AM30: 50000 | AN30: PAPER TRADING
... A370: 2026-10-29 | B370: NIFTY | C370: Both Spreads | D370: Bear Put Spread | E370: SIMULATED | F370: SKIP | G370: Conflicting — Price:BULLISH EMA:BEARISH | H370: 22777.42 | I370: 22825.21 | J370: 2026-10-29 | K370: WEEKLY | L370: 0 | M370: 09:20 IST | N370: 11:30 IST | O370: 22936.75 | P370: 22698.85 | Q370: 23000 PE | R370: 22900 PE | S370: 42 | T370: 65 | U370: 2730 | V370: 17.32 | W370: 22.52 | X370: 47283.6 | Y370: 47338.24 | Z370: 225716.4 | AA370: 14185.08 | AB370: 14185.08 | AC370: 14196 | AD370: 30 | AE370: 40 | AF370: 5.91 | AG370: 0.09 | AH370: 1.42 | AI370: 7.22 | AJ370: 54.64 | AK370: 14141.36 | AL370: PROFIT | AM370: 50000 | AN370: PAPER TRADING

Sheet NIFTY_Smart
A1: NIFTY — Smart Trend | Paper Trading
A2: Date | B2: Instrument | C2: Strategy Mode | D2: Spread | E2: Trend | F2: Trend Reason | G2: EMA 9 | H2: EMA 21 | I2: Expiry | J2: Expiry Type | K2: DTE | L2: Entry Time | M2: Exit Time | N2: Spot at Entry | O2: Prev Close | P2: Buy Strike | Q2: Sell Strike | R2: Lots | S2: Lot Size | T2: Units | U2: Entry Premium | V2: Exit Premium | W2: Total Cost (₹) | X2: Capital Used (₹) | Y2: Max Profit (₹) | Z2: Target (₹) | AA2: Stop Loss (₹) | AB2: Gross P&L (₹) | AC2: Return % | AD2: Brokerage (₹) | AE2: STT (₹) | AF2: SEBI Fee (₹) | AG2: Stamp Duty (₹) | AH2: GST (₹) | AI2: Total Fees (₹) | AJ2: Net P&L (₹) | AK2: Outcome | AL2: Budget (₹) | AM2: Mode
A3: 2026-06-18 | B3: NIFTY | C3: Smart Trend | D3: Bull Call Spread | E3: BULLISH | F3: Price↑(24168.0>24085.7) & EMA9↑(23778.35>23687.38) | G3: 23778.35 | H3: 23687.38 | I3: 2026-06-18 | J3: WEEKLY | K3: 0 | L3: 09:20 IST | M3: 11:59 IST | N3: 24168 | O3: 24085.7 | P3: 24100 CE | Q3: 24200 CE | R3: 31 | S3: 75 | T3: 2325 | U3: 20.44 | V3: 26.57 | W3: 47523 | X3: 47577.68 | Y3: 184977 | Z3: 14256.9 | AA3: 14256.9 | AB3: 14252.25 | AC3: 30 | AD3: 40 | AE3: 5.94 | AF3: 0.1 | AG3: 1.43 | AH3: 7.22 | AI3: 54.68 | AJ3: 14197.57 | AK3: PROFIT | AL3: 50000 | AM3: PAPER TRADING
